Workbook

Sheet Paper - Table 2
A1: Project Name | B1: Dynamic analysis | D1: No Analise Dinamic | G1: Code coverage | Q1: Profiling | AH1: Function-level Tracing
B2: Metrics | D2: Quantity that had to | G2: Quantity that had the Percentage of Coverage | J2: passed | M2: failed | Q2: Quantity that had the Percentage of Profiling | T2: passed ncalls | W2: failed ncalls | AA2: passed cumtime_top20 | AD2: failed cumtime_top20 | AH2: Quantity that had the Percentage of Tracing | AK2: passed Tracing_Size_Bytes (Bytes) | AN2: failed Tracing_Size_Bytes (Bytes)
B3: Test Name | C3: Hash | D3: #Passed | E3: #Failed | F3: Result | G3: #Passed | H3: #Failed | I3: Result | J3: AVG | K3: SD | L3: CV | M3: AVG | N3: SD | O3: CV | P3: Groups | Q3: #Passed | R3: #Failed | S3: Result | T3: AVG | U3: SD | V3: CV | W3: AVG | X3: SD | Y3: CV | Z3: Groups | AA3: AVG | AB3: SD | AC3: CV | AD3: AVG | AE3: SD | AF3: CV | AG3: Groups | AH3: #Passed | AI3: #Failed | AJ3: Result | AK3: AVG | AL3: SD | AM3: CV | AN3: AVG | AO3: SD | AP3: CV | AQ3: Groups | AR3: Result Final
A4: airflow | B4: test_cli.py::TestLogsfromTaskRunCommand::test_logging_with_run_task_subprocess | C4: 3133846b53e1a2803391ca17f0cf198bd3dda19602accf13567ff41106e9c994 | D4: 0 | E4: 100 | F4: =IF(AND(D4>0, E4>0), "Observed Flaky Test", "Non-observed Flaky Test") -> Non-observed Flaky Test | G4: 0 | H4: 100 | I4: =IF(AND(G4>0, H4>0), "Observed Flaky Test", "Non-observed Flaky Test") -> Non-observed Flaky Test | J4: 0 | K4: 0 | L4: =IFERROR(K4/J4*100,"N/A") -> N/A | M4: 7.73 | N4: 0 | O4: =IFERROR(N4/M4*100,"N/A") -> 0 | P4: =IF(AND(G4>0, H4=0), IF(ROUND(K4,8)=0, "Group 9: Only Passed | Without variation (SD Passed = 0)", "Group 10: Only Passed | With variation (SD Passed > 0)"), IF(AND(G4=0, H4>0), IF(ROUND(N4,8)=0, "Group 11: Only Failed | Without variation (SD Failed = 0)", "Group 12: Only Failed | With variation (SD Failed > 0)"), IF(AND(G4>0, H4>0), IF(ROUND(J4,5)<>ROUND(M4,5), IF(AND(ROUND(K4,8)=0, ROUND(N4,8)=0), "Group 1: Flaky | Passed (no variation) AND Failed (no variation) | Different Means", IF(AND(ROUND(K4,8)>0, ROUND(N4,8)>0), "Group 2: Flaky | Passed (with variation) AND Failed (with variation) | Different Means", IF(AND(ROUND(K4,8)=0, ROUND(N4,8)>0), "Group 3: Flaky | Passed (no variation) AND Failed (with variation) | Different Means", "Group 4: Flaky | Passed (with variation) AND Failed (no variation) | Different Means"))), IF(AND(ROUND(K4,8)=0, ROUND(N4,8)=0), "Group 5: Flaky | Passed (no variation) AND Failed (no variation) | Equal Means", IF(AND(ROUND(K4,8)>0, ROUND(N4,8)>0), "Group 6: Flaky | Passed (with variation) AND Failed (with variation) | Equal Means", IF(AND(ROUND(K4,8)=0, ROUND(N4,8)>0), "Group 7: Flaky | Passed (no variation) AND Failed (with variation) | Equal Means", "Group 8: Flaky | Passed (with variation) AND Failed (no variation) | Equal Means")))), "Invalid"))) -> Group 11: Only Failed | Without variation (SD Failed = 0) | Q4: 0 | R4: 100 | S4: =IF(AND(Q4>0, R4>0), "Observed Flaky Test", "Non-observed Flaky Test") -> Non-observed Flaky Test | T4: 0 | U4: 0 | V4: =IFERROR(U4/T4*100,"N/A") -> N/A | W4: 3332004.4 | X4: 18.331835 | Y4: =IFERROR(X4/W4*100,"N/A") -> 0.0005501744 | Z4: =IF(AND(Q4>0, R4=0), IF(IFERROR(ROUND(V4,8),0)=0, "Group 9: Only Passed | Without variation (no var CV = 0)", "Group 10: Only Passed | With variation (with var CV > 0)"), IF(AND(Q4=0, R4>0), IF(IFERROR(ROUND(Y4,8),0)=0, "Group 11: Only Failed | Without variation (no var CV = 0)", "Group 12: Only Failed | With variation (with var CV > 0)"), IF(AND(Q4>0, R4>0), IF(ROUND(T4,5)<>ROUND(W4,5), IF(AND(IFERROR(ROUND(V4,8),0)=0, IFERROR(ROUND(Y4,8),0)=0), "Group 1: Flaky | Passed (no variation: CV = 0) AND Failed (no variation: CV = 0) | Different Means", IF(AND(IFERROR(ROUND(V4,8),0)>0, IFERROR(ROUND(Y4,8),0)>0), "Group 2: Flaky | Passed (with variation: CV > 0) AND Failed (with variation: CV > 0) | Different Means", IF(AND(IFERROR(ROUND(V4,8),0)=0, IFERROR(ROUND(Y4,8),0)>0), "Group 3: Flaky | Passed (no variation: CV = 0) AND Failed (with variation: CV > 0) | Different Means", "Group 4: Flaky | Passed (with variation: CV > 0) AND Failed (no variation: CV = 0) | Different Means"))), IF(AND(IFERROR(ROUND(V4,8),0)=0, IFERROR(ROUND(Y4,8),0)=0), "Group 5: Flaky | Passed (no var CV = 0) AND Failed (no var CV = 0) | Equal Means", IF(AND(IFERROR(ROUND(V4,8),0)>0, IFERROR(ROUND(Y4,8),0)>0), "Group 6: Flaky | Passed (with var CV > 0) AND Failed (with var CV > 0) | Equal Means", IF(AND(IFERROR(ROUND(V4,8),0)=0, IFERROR(ROUND(Y4,8),0)>0), "Group 7: Flaky | Passed (no var CV = 0) AND Failed (with var CV > 0) | Equal Means", "Group 8: Flaky | Passed (with var CV > 0) AND Failed (no var CV = 0) | Equal Means")))), "Invalid"))) -> Group 12: Only Failed | With variation (with var CV > 0) | AA4: 0 | AB4: 0 | AC4: =IFERROR(AB4/AA4*100,"N/A") -> N/A | AD4: 2.197098 | AE4: 0.077396 | AF4: =IFERROR(AE4/AD4*100,"N/A") -> 3.5226467 | AG4: =IF(AND(Q4>0, R4=0), IF(IFERROR(ROUND(AC4,8),0)=0, "Group 9: Only Passed | Without variation (no var CV = 0)", "Group 10: Only Passed | With variation (with var CV > 0)"), IF(AND(Q4=0, R4>0), IF(IFERROR(ROUND(AF4,8),0)=0, "Group 11: Only Failed | Without variation (no var CV = 0)", "Group 12: Only Failed | With variation (with var CV > 0)"), IF(AND(Q4>0, R4>0), IF(ROUND(AA4,5)<>ROUND(AD4,5), IF(AND(IFERROR(ROUND(AC4,8),0)=0, IFERROR(ROUND(AF4,8),0)=0), "Group 1: Flaky | Passed (no variation: CV = 0) AND Failed (no variation: CV = 0) | Different Means", IF(AND(IFERROR(ROUND(AC4,8),0)>0, IFERROR(ROUND(AF4,8),0)>0), "Group 2: Flaky | Passed (with variation: CV > 0) AND Failed (with variation: CV > 0) | Different Means", IF(AND(IFERROR(ROUND(AC4,8),0)=0, IFERROR(ROUND(AF4,8),0)>0), "Group 3: Flaky | Passed (no variation: CV = 0) AND Failed (with variation: CV > 0) | Different Means", "Group 4: Flaky | Passed (with variation: CV > 0) AND Failed (no variation: CV = 0) | Different Means"))), IF(AND(IFERROR(ROUND(AC4,8),0)=0, IFERROR(ROUND(AF4,8),0)=0), "Group 5: Flaky | Passed (no var CV = 0) AND Failed (no var CV = 0) | Equal Means", IF(AND(IFERROR(ROUND(AC4,8),0)>0, IFERROR(ROUND(AF4,8),0)>0), "Group 6: Flaky | Passed (with var CV > 0) AND Failed (with var CV > 0) | Equal Means", IF(AND(IFERROR(ROUND(AC4,8),0)=0, IFERROR(ROUND(AF4,8),0)>0), "Group 7: Flaky | Passed (no var CV = 0) AND Failed (with var CV > 0) | Equal Means", "Group 8: Flaky | Passed (with var CV > 0) AND Failed (no var CV = 0) | Equal Means")))), "Invalid"))) -> Group 12: Only Failed | With variation (with var CV > 0) | AH4: 0 | AI4: 100 | AJ4: =IF(AND(AH4>0, AI4>0), "Observed Flaky Test", "Non-observed Flaky Test") -> Non-observed Flaky Test | AK4: 0 | AL4: 0 | AM4: =IFERROR(AL4/AK4*100,"N/A") -> N/A | AN4: 1781453.4 | AO4: 43.517644 | AP4: =IFERROR(AO4/AN4*100,"N/A") -> 0.0024428169 | AQ4: =IF(AND(AH4>0, AI4>0), IF(ROUND(N(AK4),5)<>ROUND(N(AN4),5), IF(AND(ROUND(N(AL4),8)=0, ROUND(N(AO4),8)=0), "Group 1: Flaky | Passed (no variation: SD = 0) AND Failed (no variation: SD = 0) | Different Means", IF(AND(ROUND(N(AL4),8)>0, ROUND(N(AO4),8)>0), "Group 2: Flaky | Passed (with variation: SD > 0) AND Failed (with variation: SD > 0) | Different Means", IF(AND(ROUND(N(AL4),8)=0, ROUND(N(AO4),8)>0), "Group 3: Flaky | Passed (no variation: SD = 0) AND Failed (with variation: SD > 0) | Different Means", "Group 4: Flaky | Passed (with variation: SD > 0) AND Failed (no variation: SD = 0) | Different Means"))), IF(AND(ROUND(N(AL4),8)=0, ROUND(N(AO4),8)=0), "Group 5: Flaky | Passed (no var SD = 0) AND Failed (no var SD = 0) | Equal Means", IF(AND(ROUND(N(AL4),8)>0, ROUND(N(AO4),8)>0), "Group 6: Flaky | Passed (with var SD > 0 ) AND Failed (with var SD > 0) | Equal Means", IF(AND(ROUND(N(AL4),8)=0, ROUND(N(AO4),8)>0), "Group 7: Flaky | Passed (no var SD = 0) AND Failed (with var SD > 0) | Equal Means", "Group 8: Flaky | Passed (with var SD > 0 ) AND Failed (no var SD = 0) | Equal Means"))) ), IF(AH4>0, IF(N(AL4)>0, "Group 10: Only Passed | With variation (with var SD > 0)", "Group 9: Only Passed | Without variation (no var SD = 0)"), IF(AI4>0, IF(N(AO4)>0, "Group 12: Only Failed | With variation (with var SD > 0)", "Group 11: Only Failed | Without variation (no var SD = 0)"), "Invalid: No Executions (Y=0, Z=0)" ) ) ) -> Group 12: Only Failed | With variation (with var SD > 0) | AR4: =IF(OR(F4="Observed Flaky Test", I4="Observed Flaky Test", S4="Observed Flaky Test", AJ4="Observed Flaky Test"), "Observed Flaky Test", "Non-observed Flaky Test") -> Non-observed Flaky Test
B5: test_python_sensor.py::PythonSensorTests::test_python_callable_arguments_are_templatized | C5: e48d4714cab9c53c8d93072b739458862b362deb18906f35f86ba87910b4c82b | D5: 100 | E5: 0 | F5: =IF(AND(D5>0, E5>0), "Observed Flaky Test", "Non-observed Flaky Test") -> Non-observed Flaky Test | G5: 0 | H5: 100 | I5: =IF(AND(G5>0, H5>0), "Observed Flaky Test", "Non-observed Flaky Test") -> Non-observed Flaky Test | J5: 0 | K5: 0 | L5: =IFERROR(K5/J5*100,"N/A") -> N/A | M5: 4.92 | N5: 0 | O5: =IFERROR(N5/M5*100,"N/A") -> 0 | P5: =IF(AND(G5>0, H5=0), IF(ROUND(K5,8)=0, "Group 9: Only Passed | Without variation (SD Passed = 0)", "Group 10: Only Passed | With variation (SD Passed > 0)"), IF(AND(G5=0, H5>0), IF(ROUND(N5,8)=0, "Group 11: Only Failed | Without variation (SD Failed = 0)", "Group 12: Only Failed | With variation (SD Failed > 0)"), IF(AND(G5>0, H5>0), IF(ROUND(J5,5)<>ROUND(M5,5), IF(AND(ROUND(K5,8)=0, ROUND(N5,8)=0), "Group 1: Flaky | Passed (no variation) AND Failed (no variation) | Different Means", IF(AND(ROUND(K5,8)>0, ROUND(N5,8)>0), "Group 2: Flaky | Passed (with variation) AND Failed (with variation) | Different Means", IF(AND(ROUND(K5,8)=0, ROUND(N5,8)>0), "Group 3: Flaky | Passed (no variation) AND Failed (with variation) | Different Means", "Group 4: Flaky | Passed (with variation) AND Failed (no variation) | Different Means"))), IF(AND(ROUND(K5,8)=0, ROUND(N5,8)=0), "Group 5: Flaky | Passed (no variation) AND Failed (no variation) | Equal Means", IF(AND(ROUND(K5,8)>0, ROUND(N5,8)>0), "Group 6: Flaky | Passed (with variation) AND Failed (with variation) | Equal Means", IF(AND(ROUND(K5,8)=0, ROUND(N5,8)>0), "Group 7: Flaky | Passed (no variation) AND Failed (with variation) | Equal Means", "Group 8: Flaky | Passed (with variation) AND Failed (no variation) | Equal Means")))), "Invalid"))) -> Group 11: Only Failed | Without variation (SD Failed = 0) | Q5: 0 | R5: 100 | S5: =IF(AND(Q5>0, R5>0), "Observed Flaky Test", "Non-observed Flaky Test") -> Non-observed Flaky Test | T5: 0 | U5: 0 | V5: =IFERROR(U5/T5*100,"N/A") -> N/A | W5: 2277580.1 | X5: 216703.62 | Y5: =IFERROR(X5/W5*100,"N/A") -> 9.5146433 | Z5: =IF(AND(Q5>0, R5=0), IF(IFERROR(ROUND(V5,8),0)=0, "Group 9: Only Passed | Without variation (no var CV = 0)", "Group 10: Only Passed | With variation (with var CV > 0)"), IF(AND(Q5=0, R5>0), IF(IFERROR(ROUND(Y5,8),0)=0, "Group 11: Only Failed | Without variation (no var CV = 0)", "Group 12: Only Failed | With variation (with var CV > 0)"), IF(AND(Q5>0, R5>0), IF(ROUND(T5,5)<>ROUND(W5,5), IF(AND(IFERROR(ROUND(V5,8),0)=0, IFERROR(ROUND(Y5,8),0)=0), "Group 1: Flaky | Passed (no variation: CV = 0) AND Failed (no variation: CV = 0) | Different Means", IF(AND(IFERROR(ROUND(V5,8),0)>0, IFERROR(ROUND(Y5,8),0)>0), "Group 2: Flaky | Passed (with variation: CV > 0) AND Failed (with variation: CV > 0) | Different Means", IF(AND(IFERROR(ROUND(V5,8),0)=0, IFERROR(ROUND(Y5,8),0)>0), "Group 3: Flaky | Passed (no variation: CV = 0) AND Failed (with variation: CV > 0) | Different Means", "Group 4: Flaky | Passed (with variation: CV > 0) AND Failed (no variation: CV = 0) | Different Means"))), IF(AND(IFERROR(ROUND(V5,8),0)=0, IFERROR(ROUND(Y5,8),0)=0), "Group 5: Flaky | Passed (no var CV = 0) AND Failed (no var CV = 0) | Equal Means", IF(AND(IFERROR(ROUND(V5,8),0)>0, IFERROR(ROUND(Y5,8),0)>0), "Group 6: Flaky | Passed (with var CV > 0) AND Failed (with var CV > 0) | Equal Means", IF(AND(IFERROR(ROUND(V5,8),0)=0, IFERROR(ROUND(Y5,8),0)>0), "Group 7: Flaky | Passed (no var CV = 0) AND Failed (with var CV > 0) | Equal Means", "Group 8: Flaky | Passed (with var CV > 0) AND Failed (no var CV = 0) | Equal Means")))), "Invalid"))) -> Group 12: Only Failed | With variation (with var CV > 0) | AA5: 0 | AB5: 0 | AC5: =IFERROR(AB5/AA5*100,"N/A") -> N/A | AD5: 1.435702 | AE5: 0.120186 | AF5: =IFERROR(AE5/AD5*100,"N/A") -> 8.3712358 | AG5: =IF(AND(Q5>0, R5=0), IF(IFERROR(ROUND(AC5,8),0)=0, "Group 9: Only Passed | Without variation (no var CV = 0)", "Group 10: Only Passed | With variation (with var CV > 0)"), IF(AND(Q5=0, R5>0), IF(IFERROR(ROUND(AF5,8),0)=0, "Group 11: Only Failed | Without variation (no var CV = 0)", "Group 12: Only Failed | With variation (with var CV > 0)"), IF(AND(Q5>0, R5>0), IF(ROUND(AA5,5)<>ROUND(AD5,5), IF(AND(IFERROR(ROUND(AC5,8),0)=0, IFERROR(ROUND(AF5,8),0)=0), "Group 1: Flaky | Passed (no variation: CV = 0) AND Failed (no variation: CV = 0) | Different Means", IF(AND(IFERROR(ROUND(AC5,8),0)>0, IFERROR(ROUND(AF5,8),0)>0), "Group 2: Flaky | Passed (with variation: CV > 0) AND Failed (with variation: CV > 0) | Different Means", IF(AND(IFERROR(ROUND(AC5,8),0)=0, IFERROR(ROUND(AF5,8),0)>0), "Group 3: Flaky | Passed (no variation: CV = 0) AND Failed (with variation: CV > 0) | Different Means", "Group 4: Flaky | Passed (with variation: CV > 0) AND Failed (no variation: CV = 0) | Different Means"))), IF(AND(IFERROR(ROUND(AC5,8),0)=0, IFERROR(ROUND(AF5,8),0)=0), "Group 5: Flaky | Passed (no var CV = 0) AND Failed (no var CV = 0) | Equal Means", IF(AND(IFERROR(ROUND(AC5,8),0)>0, IFERROR(ROUND(AF5,8),0)>0), "Group 6: Flaky | Passed (with var CV > 0) AND Failed (with var CV > 0) | Equal Means", IF(AND(IFERROR(ROUND(AC5,8),0)=0, IFERROR(ROUND(AF5,8),0)>0), "Group 7: Flaky | Passed (no var CV = 0) AND Failed (with var CV > 0) | Equal Means", "Group 8: Flaky | Passed (with var CV > 0) AND Failed (no var CV = 0) | Equal Means")))), "Invalid"))) -> Group 12: Only Failed | With variation (with var CV > 0) | AH5: 1 | AI5: 99 | AJ5: =IF(AND(AH5>0, AI5>0), "Observed Flaky Test", "Non-observed Flaky Test") -> Observed Flaky Test | AK5: 96333 | AL5: 0 | AM5: =IFERROR(AL5/AK5*100,"N/A") -> 0 | AN5: 63403.848 | AO5: 20.314046 | AP5: =IFERROR(AO5/AN5*100,"N/A") -> 0.032039138 | AQ5: =IF(AND(AH5>0, AI5>0), IF(ROUND(N(AK5),5)<>ROUND(N(AN5),5), IF(AND(ROUND(N(AL5),8)=0, ROUND(N(AO5),8)=0), "Group 1: Flaky | Passed (no variation: SD = 0) AND Failed (no variation: SD = 0) | Different Means", IF(AND(ROUND(N(AL5),8)>0, ROUND(N(AO5),8)>0), "Group 2: Flaky | Passed (with variation: SD > 0) AND Failed (with variation: SD > 0) | Different Means", IF(AND(ROUND(N(AL5),8)=0, ROUND(N(AO5),8)>0), "Group 3: Flaky | Passed (no variation: SD = 0) AND Failed (with variation: SD > 0) | Different Means", "Group 4: Flaky | Passed (with variation: SD > 0) AND Failed (no variation: SD = 0) | Different Means"))), IF(AND(ROUND(N(AL5),8)=0, ROUND(N(AO5),8)=0), "Group 5: Flaky | Passed (no var SD = 0) AND Failed (no var SD = 0) | Equal Means", IF(AND(ROUND(N(AL5),8)>0, ROUND(N(AO5),8)>0), "Group 6: Flaky | Passed (with var SD > 0 ) AND Failed (with var SD > 0) | Equal Means", IF(AND(ROUND(N(AL5),8)=0, ROUND(N(AO5),8)>0), "Group 7: Flaky | Passed (no var SD = 0) AND Failed (with var SD > 0) | Equal Means", "Group 8: Flaky | Passed (with var SD > 0 ) AND Failed (no var SD = 0) | Equal Means"))) ), IF(AH5>0, IF(N(AL5)>0, "Group 10: Only Passed | With variation (with var SD > 0)", "Group 9: Only Passed | Without variation (no var SD = 0)"), IF(AI5>0, IF(N(AO5)>0, "Group 12: Only Failed | With variation (with var SD > 0)", "Group 11: Only Failed | Without variation (no var SD = 0)"), "Invalid: No Executions (Y=0, Z=0)" ) ) ) -> Group 3: Flaky | Passed (no variation: SD = 0) AND Failed (with variation: SD > 0) | Different Means | AR5: =IF(OR(F5="Observed Flaky Test", I5="Observed Flaky Test", S5="Observed Flaky Test", AJ5="Observed Flaky Test"), "Observed Flaky Test", "Non-observed Flaky Test") -> Observed Flaky Test
B6: test_python_sensor.py::PythonSensorTests::test_python_callable_keyword_arguments_are_templatized | C6: b0bd0cae2d72647c8ddc8e244d41680ae0aa27c8e3be56db73777ad39e728bd5 | D6: 100 | E6: 0 | F6: =IF(AND(D6>0, E6>0), "Observed Flaky Test", "Non-observed Flaky Test") -> Non-observed Flaky Test | G6: 0 | H6: 100 | I6: =IF(AND(G6>0, H6>0), "Observed Flaky Test", "Non-observed Flaky Test") -> Non-observed Flaky Test | J6: 0 | K6: 0 | L6: =IFERROR(K6/J6*100,"N/A") -> N/A | M6: 4.92 | N6: 0 | O6: =IFERROR(N6/M6*100,"N/A") -> 0 | P6: =IF(AND(G6>0, H6=0), IF(ROUND(K6,8)=0, "Group 9: Only Passed | Without variation (SD Passed = 0)", "Group 10: Only Passed | With variation (SD Passed > 0)"), IF(AND(G6=0, H6>0), IF(ROUND(N6,8)=0, "Group 11: Only Failed | Without variation (SD Failed = 0)", "Group 12: Only Failed | With variation (SD Failed > 0)"), IF(AND(G6>0, H6>0), IF(ROUND(J6,5)<>ROUND(M6,5), IF(AND(ROUND(K6,8)=0, ROUND(N6,8)=0), "Group 1: Flaky | Passed (no variation) AND Failed (no variation) | Different Means", IF(AND(ROUND(K6,8)>0, ROUND(N6,8)>0), "Group 2: Flaky | Passed (with variation) AND Failed (with variation) | Different Means", IF(AND(ROUND(K6,8)=0, ROUND(N6,8)>0), "Group 3: Flaky | Passed (no variation) AND Failed (with variation) | Different Means", "Group 4: Flaky | Passed (with variation) AND Failed (no variation) | Different Means"))), IF(AND(ROUND(K6,8)=0, ROUND(N6,8)=0), "Group 5: Flaky | Passed (no variation) AND Failed (no variation) | Equal Means", IF(AND(ROUND(K6,8)>0, ROUND(N6,8)>0), "Group 6: Flaky | Passed (with variation) AND Failed (with variation) | Equal Means", IF(AND(ROUND(K6,8)=0, ROUND(N6,8)>0), "Group 7: Flaky | Passed (no variation) AND Failed (with variation) | Equal Means", "Group 8: Flaky | Passed (with variation) AND Failed (no variation) | Equal Means")))), "Invalid"))) -> Group 11: Only Failed | Without variation (SD Failed = 0) | Q6: 1 | R6: 99 | S6: =IF(AND(Q6>0, R6>0), "Observed Flaky Test", "Non-observed Flaky Test") -> Observed Flaky Test | T6: 1917838 | U6: 0 | V6: =IFERROR(U6/T6*100,"N/A") -> 0 | W6: 2255494.3 | X6: 15.147805 | Y6: =IFERROR(X6/W6*100,"N/A") -> 0.00067159581 | Z6: =IF(AND(Q6>0, R6=0), IF(IFERROR(ROUND(V6,8),0)=0, "Group 9: Only Passed | Without variation (no var CV = 0)", "Group 10: Only Passed | With variation (with var CV > 0)"), IF(AND(Q6=0, R6>0), IF(IFERROR(ROUND(Y6,8),0)=0, "Group 11: Only Failed | Without variation (no var CV = 0)", "Group 12: Only Failed | With variation (with var CV > 0)"), IF(AND(Q6>0, R6>0), IF(ROUND(T6,5)<>ROUND(W6,5), IF(AND(IFERROR(ROUND(V6,8),0)=0, IFERROR(ROUND(Y6,8),0)=0), "Group 1: Flaky | Passed (no variation: CV = 0) AND Failed (no variation: CV = 0) | Different Means", IF(AND(IFERROR(ROUND(V6,8),0)>0, IFERROR(ROUND(Y6,8),0)>0), "Group 2: Flaky | Passed (with variation: CV > 0) AND Failed (with variation: CV > 0) | Different Means", IF(AND(IFERROR(ROUND(V6,8),0)=0, IFERROR(ROUND(Y6,8),0)>0), "Group 3: Flaky | Passed (no variation: CV = 0) AND Failed (with variation: CV > 0) | Different Means", "Group 4: Flaky | Passed (with variation: CV > 0) AND Failed (no variation: CV = 0) | Different Means"))), IF(AND(IFERROR(ROUND(V6,8),0)=0, IFERROR(ROUND(Y6,8),0)=0), "Group 5: Flaky | Passed (no var CV = 0) AND Failed (no var CV = 0) | Equal Means", IF(AND(IFERROR(ROUND(V6,8),0)>0, IFERROR(ROUND(Y6,8),0)>0), "Group 6: Flaky | Passed (with var CV > 0) AND Failed (with var CV > 0) | Equal Means", IF(AND(IFERROR(ROUND(V6,8),0)=0, IFERROR(ROUND(Y6,8),0)>0), "Group 7: Flaky | Passed (no var CV = 0) AND Failed (with var CV > 0) | Equal Means", "Group 8: Flaky | Passed (with var CV > 0) AND Failed (no var CV = 0) | Equal Means")))), "Invalid"))) -> Group 3: Flaky | Passed (no variation: CV = 0) AND Failed (with variation: CV > 0) | Different Means | AA6: 1.859104 | AB6: 0 | AC6: =IFERROR(AB6/AA6*100,"N/A") -> 0 | AD6: 1.377134 | AE6: 0.051632 | AF6: =IFERROR(AE6/AD6*100,"N/A") -> 3.7492357 | AG6: =IF(AND(Q6>0, R6=0), IF(IFERROR(ROUND(AC6,8),0)=0, "Group 9: Only Passed | Without variation (no var CV = 0)", "Group 10: Only Passed | With variation (with var CV > 0)"), IF(AND(Q6=0, R6>0), IF(IFERROR(ROUND(AF6,8),0)=0, "Group 11: Only Failed | Without variation (no var CV = 0)", "Group 12: Only Failed | With variation (with var CV > 0)"), IF(AND(Q6>0, R6>0), IF(ROUND(AA6,5)<>ROUND(AD6,5), IF(AND(IFERROR(ROUND(AC6,8),0)=0, IFERROR(ROUND(AF6,8),0)=0), "Group 1: Flaky | Passed (no variation: CV = 0) AND Failed (no variation: CV = 0) | Different Means", IF(AND(IFERROR(ROUND(AC6,8),0)>0, IFERROR(ROUND(AF6,8),0)>0), "Group 2: Flaky | Passed (with variation: CV > 0) AND Failed (with variation: CV > 0) | Different Means", IF(AND(IFERROR(ROUND(AC6,8),0)=0, IFERROR(ROUND(AF6,8),0)>0), "Group 3: Flaky | Passed (no variation: CV = 0) AND Failed (with variation: CV > 0) | Different Means", "Group 4: Flaky | Passed (with variation: CV > 0) AND Failed (no variation: CV = 0) | Different Means"))), IF(AND(IFERROR(ROUND(AC6,8),0)=0, IFERROR(ROUND(AF6,8),0)=0), "Group 5: Flaky | Passed (no var CV = 0) AND Failed (no var CV = 0) | Equal Means", IF(AND(IFERROR(ROUND(AC6,8),0)>0, IFERROR(ROUND(AF6,8),0)>0), "Group 6: Flaky | Passed (with var CV > 0) AND Failed (with var CV > 0) | Equal Means", IF(AND(IFERROR(ROUND(AC6,8),0)=0, IFERROR(ROUND(AF6,8),0)>0), "Group 7: Flaky | Passed (no var CV = 0) AND Failed (with var CV > 0) | Equal Means", "Group 8: Flaky | Passed (with var CV > 0) AND Failed (no var CV = 0) | Equal Means")))), "Invalid"))) -> Group 3: Flaky | Passed (no variation: CV = 0) AND Failed (with variation: CV > 0) | Different Means | AH6: 1 | AI6: 99 | AJ6: =IF(AND(AH6>0, AI6>0), "Observed Flaky Test", "Non-observed Flaky Test") -> Observed Flaky Test | AK6: 93304 | AL6: 0 | AM6: =IFERROR(AL6/AK6*100,"N/A") -> 0 | AN6: 63403.828 | AO6: 22.937377 | AP6: =IFERROR(AO6/AN6*100,"N/A") -> 0.036176644 | AQ6: =IF(AND(AH6>0, AI6>0), IF(ROUND(N(AK6),5)<>ROUND(N(AN6),5), IF(AND(ROUND(N(AL6),8)=0, ROUND(N(AO6),8)=0), "Group 1: Flaky | Passed (no variation: SD = 0) AND Failed (no variation: SD = 0) | Different Means", IF(AND(ROUND(N(AL6),8)>0, ROUND(N(AO6),8)>0), "Group 2: Flaky | Passed (with variation: SD > 0) AND Failed (with variation: SD > 0) | Different Means", IF(AND(ROUND(N(AL6),8)=0, ROUND(N(AO6),8)>0), "Group 3: Flaky | Passed (no variation: SD = 0) AND Failed (with variation: SD > 0) | Different Means", "Group 4: Flaky | Passed (with variation: SD > 0) AND Failed (no variation: SD = 0) | Different Means"))), IF(AND(ROUND(N(AL6),8)=0, ROUND(N(AO6),8)=0), "Group 5: Flaky | Passed (no var SD = 0) AND Failed (no var SD = 0) | Equal Means", IF(AND(ROUND(N(AL6),8)>0, ROUND(N(AO6),8)>0), "Group 6: Flaky | Passed (with var SD > 0 ) AND Failed (with var SD > 0) | Equal Means", IF(AND(ROUND(N(AL6),8)=0, ROUND(N(AO6),8)>0), "Group 7: Flaky | Passed (no var SD = 0) AND Failed (with var SD > 0) | Equal Means", "Group 8: Flaky | Passed (with var SD > 0 ) AND Failed (no var SD = 0) | Equal Means"))) ), IF(AH6>0, IF(N(AL6)>0, "Group 10: Only Passed | With variation (with var SD > 0)", "Group 9: Only Passed | Without variation (no var SD = 0)"), IF(AI6>0, IF(N(AO6)>0, "Group 12: Only Failed | With variation (with var SD > 0)", "Group 11: Only Failed | Without variation (no var SD = 0)"), "Invalid: No Executions (Y=0, Z=0)" ) ) ) -> Group 3: Flaky | Passed (no variation: SD = 0) AND Failed (with variation: SD > 0) | Different Means | AR6: =IF(OR(F6="Observed Flaky Test", I6="Observed Flaky Test", S6="Observed Flaky Test", AJ6="Observed Flaky Test"), "Observed Flaky Test", "Non-observed Flaky Test") -> Observed Flaky Test
B7: test_core.py::CliTests::test_cli_connections_add_delete | C7: 3f82253b0e70dccbf314ef4dab9556ad88dd925374f24af4bf450b02a1221d9e | D7: 100 | E7: 0 | F7: =IF(AND(D7>0, E7>0), "Observed Flaky Test", "Non-observed Flaky Test") -> Non-observed Flaky Test | G7: 100 | H7: 0 | I7: =IF(AND(G7>0, H7>0), "Observed Flaky Test", "Non-observed Flaky Test") -> Non-observed Flaky Test | J7: 8.7804 | K7: 0.00196 | L7: =IFERROR(K7/J7*100,"N/A") -> 0.022322445 | M7: 0 | N7: 0 | O7: =IFERROR(N7/M7*100,"N/A") -> N/A | P7: =IF(AND(G7>0, H7=0), IF(ROUND(K7,8)=0, "Group 9: Only Passed | Without variation (SD Passed = 0)", "Group 10: Only Passed | With variation (SD Passed > 0)"), IF(AND(G7=0, H7>0), IF(ROUND(N7,8)=0, "Group 11: Only Failed | Without variation (SD Failed = 0)", "Group 12: Only Failed | With variation (SD Failed > 0)"), IF(AND(G7>0, H7>0), IF(ROUND(J7,5)<>ROUND(M7,5), IF(AND(ROUND(K7,8)=0, ROUND(N7,8)=0), "Group 1: Flaky | Passed (no variation) AND Failed (no variation) | Different Means", IF(AND(ROUND(K7,8)>0, ROUND(N7,8)>0), "Group 2: Flaky | Passed (with variation) AND Failed (with variation) | Different Means", IF(AND(ROUND(K7,8)=0, ROUND(N7,8)>0), "Group 3: Flaky | Passed (no variation) AND Failed (with variation) | Different Means", "Group 4: Flaky | Passed (with variation) AND Failed (no variation) | Different Means"))), IF(AND(ROUND(K7,8)=0, ROUND(N7,8)=0), "Group 5: Flaky | Passed (no variation) AND Failed (no variation) | Equal Means", IF(AND(ROUND(K7,8)>0, ROUND(N7,8)>0), "Group 6: Flaky | Passed (with variation) AND Failed (with variation) | Equal Means", IF(AND(ROUND(K7,8)=0, ROUND(N7,8)>0), "Group 7: Flaky | Passed (no variation) AND Failed (with variation) | Equal Means", "Group 8: Flaky | Passed (with variation) AND Failed (no variation) | Equal Means")))), "Invalid"))) -> Group 10: Only Passed | With variation (SD Passed > 0) | Q7: 100 | R7: 0 | S7: =IF(AND(Q7>0, R7>0), "Observed Flaky Test", "Non-observed Flaky Test") -> Non-observed Flaky Test | T7: 4320204 | U7: 283.89484 | V7: =IFERROR(U7/T7*100,"N/A") -> 0.0065713296 | W7: 0 | X7: 0 | Y7: =IFERROR(X7/W7*100,"N/A") -> N/A | Z7: =IF(AND(Q7>0, R7=0), IF(IFERROR(ROUND(V7,8),0)=0, "Group 9: Only Passed | Without variation (no var CV = 0)", "Group 10: Only Passed | With variation (with var CV > 0)"), IF(AND(Q7=0, R7>0), IF(IFERROR(ROUND(Y7,8),0)=0, "Group 11: Only Failed | Without variation (no var CV = 0)", "Group 12: Only Failed | With variation (with var CV > 0)"), IF(AND(Q7>0, R7>0), IF(ROUND(T7,5)<>ROUND(W7,5), IF(AND(IFERROR(ROUND(V7,8),0)=0, IFERROR(ROUND(Y7,8),0)=0), "Group 1: Flaky | Passed (no variation: CV = 0) AND Failed (no variation: CV = 0) | Different Means", IF(AND(IFERROR(ROUND(V7,8),0)>0, IFERROR(ROUND(Y7,8),0)>0), "Group 2: Flaky | Passed (with variation: CV > 0) AND Failed (with variation: CV > 0) | Different Means", IF(AND(IFERROR(ROUND(V7,8),0)=0, IFERROR(ROUND(Y7,8),0)>0), "Group 3: Flaky | Passed (no variation: CV = 0) AND Failed (with variation: CV > 0) | Different Means", "Group 4: Flaky | Passed (with variation: CV > 0) AND Failed (no variation: CV = 0) | Different Means"))), IF(AND(IFERROR(ROUND(V7,8),0)=0, IFERROR(ROUND(Y7,8),0)=0), "Group 5: Flaky | Passed (no var CV = 0) AND Failed (no var CV = 0) | Equal Means", IF(AND(IFERROR(ROUND(V7,8),0)>0, IFERROR(ROUND(Y7,8),0)>0), "Group 6: Flaky | Passed (with var CV > 0) AND Failed (with var CV > 0) | Equal Means", IF(AND(IFERROR(ROUND(V7,8),0)=0, IFERROR(ROUND(Y7,8),0)>0), "Group 7: Flaky | Passed (no var CV = 0) AND Failed (with var CV > 0) | Equal Means", "Group 8: Flaky | Passed (with var CV > 0) AND Failed (no var CV = 0) | Equal Means")))), "Invalid"))) -> Group 10: Only Passed | With variation (with var CV > 0) | AA7: 2.568642 | AB7: 0.081876 | AC7: =IFERROR(AB7/AA7*100,"N/A") -> 3.1875209 | AD7: 0 | AE7: 0 | AF7: =IFERROR(AE7/AD7*100,"N/A") -> N/A | AG7: =IF(AND(Q7>0, R7=0), IF(IFERROR(ROUND(AC7,8),0)=0, "Group 9: Only Passed | Without variation (no var CV = 0)", "Group 10: Only Passed | With variation (with var CV > 0)"), IF(AND(Q7=0, R7>0), IF(IFERROR(ROUND(AF7,8),0)=0, "Group 11: Only Failed | Without variation (no var CV = 0)", "Group 12: Only Failed | With variation (with var CV > 0)"), IF(AND(Q7>0, R7>0), IF(ROUND(AA7,5)<>ROUND(AD7,5), IF(AND(IFERROR(ROUND(AC7,8),0)=0, IFERROR(ROUND(AF7,8),0)=0), "Group 1: Flaky | Passed (no variation: CV = 0) AND Failed (no variation: CV = 0) | Different Means", IF(AND(IFERROR(ROUND(AC7,8),0)>0, IFERROR(ROUND(AF7,8),0)>0), "Group 2: Flaky | Passed (with variation: CV > 0) AND Failed (with variation: CV > 0) | Different Means", IF(AND(IFERROR(ROUND(AC7,8),0)=0, IFERROR(ROUND(AF7,8),0)>0), "Group 3: Flaky | Passed (no variation: CV = 0) AND Failed (with variation: CV > 0) | Different Means", "Group 4: Flaky | Passed (with variation: CV > 0) AND Failed (no variation: CV = 0) | Different Means"))), IF(AND(IFERROR(ROUND(AC7,8),0)=0, IFERROR(ROUND(AF7,8),0)=0), "Group 5: Flaky | Passed (no var CV = 0) AND Failed (no var CV = 0) | Equal Means", IF(AND(IFERROR(ROUND(AC7,8),0)>0, IFERROR(ROUND(AF7,8),0)>0), "Group 6: Flaky | Passed (with var CV > 0) AND Failed (with var CV > 0) | Equal Means", IF(AND(IFERROR(ROUND(AC7,8),0)=0, IFERROR(ROUND(AF7,8),0)>0), "Group 7: Flaky | Passed (no var CV = 0) AND Failed (with var CV > 0) | Equal Means", "Group 8: Flaky | Passed (with var CV > 0) AND Failed (no var CV = 0) | Equal Means")))), "Invalid"))) -> Group 10: Only Passed | With variation (with var CV > 0) | AH7: 100 | AI7: 0 | AJ7: =IF(AND(AH7>0, AI7>0), "Observed Flaky Test", "Non-observed Flaky Test") -> Non-observed Flaky Test | AK7: 2865901.5 | AL7: 81.546474 | AM7: =IFERROR(AL7/AK7*100,"N/A") -> 0.0028454039 | AN7: 0 | AO7: 0 | AP7: =IFERROR(AO7/AN7*100,"N/A") -> N/A | AQ7: =IF(AND(AH7>0, AI7>0), IF(ROUND(N(AK7),5)<>ROUND(N(AN7),5), IF(AND(ROUND(N(AL7),8)=0, ROUND(N(AO7),8)=0), "Group 1: Flaky | Passed (no variation: SD = 0) AND Failed (no variation: SD = 0) | Different Means", IF(AND(ROUND(N(AL7),8)>0, ROUND(N(AO7),8)>0), "Group 2: Flaky | Passed (with variation: SD > 0) AND Failed (with variation: SD > 0) | Different Means", IF(AND(ROUND(N(AL7),8)=0, ROUND(N(AO7),8)>0), "Group 3: Flaky | Passed (no variation: SD = 0) AND Failed (with variation: SD > 0) | Different Means", "Group 4: Flaky | Passed (with variation: SD > 0) AND Failed (no variation: SD = 0) | Different Means"))), IF(AND(ROUND(N(AL7),8)=0, ROUND(N(AO7),8)=0), "Group 5: Flaky | Passed (no var SD = 0) AND Failed (no var SD = 0) | Equal Means", IF(AND(ROUND(N(AL7),8)>0, ROUND(N(AO7),8)>0), "Group 6: Flaky | Passed (with var SD > 0 ) AND Failed (with var SD > 0) | Equal Means", IF(AND(ROUND(N(AL7),8)=0, ROUND(N(AO7),8)>0), "Group 7: Flaky | Passed (no var SD = 0) AND Failed (with var SD > 0) | Equal Means", "Group 8: Flaky | Passed (with var SD > 0 ) AND Failed (no var SD = 0) | Equal Means"))) ), IF(AH7>0, IF(N(AL7)>0, "Group 10: Only Passed | With variation (with var SD > 0)", "Group 9: Only Passed | Without variation (no var SD = 0)"), IF(AI7>0, IF(N(AO7)>0, "Group 12: Only Failed | With variation (with var SD > 0)", "Group 11: Only Failed | Without variation (no var SD = 0)"), "Invalid: No Executions (Y=0, Z=0)" ) ) ) -> Group 10: Only Passed | With variation (with var SD > 0) | AR7: =IF(OR(F7="Observed Flaky Test", I7="Observed Flaky Test", S7="Observed Flaky Test", AJ7="Observed Flaky Test"), "Observed Flaky Test", "Non-observed Flaky Test") -> Non-observed Flaky Test
B8: test_core.py::CliTests::test_cli_connections_list_redirect | C8: 2afaa97935135aa44fc2c22efa62c55793ef453d50fbdaabb952e9cc4be5d896 | D8: 0 | E8: 100 | F8: =IF(AND(D8>0, E8>0), "Observed Flaky Test", "Non-observed Flaky Test") -> Non-observed Flaky Test | G8: 0 | H8: 100 | I8: =IF(AND(G8>0, H8>0), "Observed Flaky Test", "Non-observed Flaky Test") -> Non-observed Flaky Test | J8: 0 | K8: 0 | L8: =IFERROR(K8/J8*100,"N/A") -> N/A | M8: 8.5109 | N8: 0.002862 | O8: =IFERROR(N8/M8*100,"N/A") -> 0.033627466 | P8: =IF(AND(G8>0, H8=0), IF(ROUND(K8,8)=0, "Group 9: Only Passed | Without variation (SD Passed = 0)", "Group 10: Only Passed | With variation (SD Passed > 0)"), IF(AND(G8=0, H8>0), IF(ROUND(N8,8)=0, "Group 11: Only Failed | Without variation (SD Failed = 0)", "Group 12: Only Failed | With variation (SD Failed > 0)"), IF(AND(G8>0, H8>0), IF(ROUND(J8,5)<>ROUND(M8,5), IF(AND(ROUND(K8,8)=0, ROUND(N8,8)=0), "Group 1: Flaky | Passed (no variation) AND Failed (no variation) | Different Means", IF(AND(ROUND(K8,8)>0, ROUND(N8,8)>0), "Group 2: Flaky | Passed (with variation) AND Failed (with variation) | Different Means", IF(AND(ROUND(K8,8)=0, ROUND(N8,8)>0), "Group 3: Flaky | Passed (no variation) AND Failed (with variation) | Different Means", "Group 4: Flaky | Passed (with variation) AND Failed (no variation) | Different Means"))), IF(AND(ROUND(K8,8)=0, ROUND(N8,8)=0), "Group 5: Flaky | Passed (no variation) AND Failed (no variation) | Equal Means", IF(AND(ROUND(K8,8)>0, ROUND(N8,8)>0), "Group 6: Flaky | Passed (with variation) AND Failed (with variation) | Equal Means", IF(AND(ROUND(K8,8)=0, ROUND(N8,8)>0), "Group 7: Flaky | Passed (no variation) AND Failed (with variation) | Equal Means", "Group 8: Flaky | Passed (with variation) AND Failed (no variation) | Equal Means")))), "Invalid"))) -> Group 12: Only Failed | With variation (SD Failed > 0) | Q8: 0 | R8: 100 | S8: =IF(AND(Q8>0, R8>0), "Observed Flaky Test", "Non-observed Flaky Test") -> Non-observed Flaky Test | T8: 0 | U8: 0 | V8: =IFERROR(U8/T8*100,"N/A") -> N/A | W8: 4916823 | X8: 148.87219 | Y8: =IFERROR(X8/W8*100,"N/A") -> 0.0030278127 | Z8: =IF(AND(Q8>0, R8=0), IF(IFERROR(ROUND(V8,8),0)=0, "Group 9: Only Passed | Without variation (no var CV = 0)", "Group 10: Only Passed | With variation (with var CV > 0)"), IF(AND(Q8=0, R8>0), IF(IFERROR(ROUND(Y8,8),0)=0, "Group 11: Only Failed | Without variation (no var CV = 0)", "Group 12: Only Failed | With variation (with var CV > 0)"), IF(AND(Q8>0, R8>0), IF(ROUND(T8,5)<>ROUND(W8,5), IF(AND(IFERROR(ROUND(V8,8),0)=0, IFERROR(ROUND(Y8,8),0)=0), "Group 1: Flaky | Passed (no variation: CV = 0) AND Failed (no variation: CV = 0) | Different Means", IF(AND(IFERROR(ROUND(V8,8),0)>0, IFERROR(ROUND(Y8,8),0)>0), "Group 2: Flaky | Passed (with variation: CV > 0) AND Failed (with variation: CV > 0) | Different Means", IF(AND(IFERROR(ROUND(V8,8),0)=0, IFERROR(ROUND(Y8,8),0)>0), "Group 3: Flaky | Passed (no variation: CV = 0) AND Failed (with variation: CV > 0) | Different Means", "Group 4: Flaky | Passed (with variation: CV > 0) AND Failed (no variation: CV = 0) | Different Means"))), IF(AND(IFERROR(ROUND(V8,8),0)=0, IFERROR(ROUND(Y8,8),0)=0), "Group 5: Flaky | Passed (no var CV = 0) AND Failed (no var CV = 0) | Equal Means", IF(AND(IFERROR(ROUND(V8,8),0)>0, IFERROR(ROUND(Y8,8),0)>0), "Group 6: Flaky | Passed (with var CV > 0) AND Failed (with var CV > 0) | Equal Means", IF(AND(IFERROR(ROUND(V8,8),0)=0, IFERROR(ROUND(Y8,8),0)>0), "Group 7: Flaky | Passed (no var CV = 0) AND Failed (with var CV > 0) | Equal Means", "Group 8: Flaky | Passed (with var CV > 0) AND Failed (no var CV = 0) | Equal Means")))), "Invalid"))) -> Group 12: Only Failed | With variation (with var CV > 0) | AA8: 0 | AB8: 0 | AC8: =IFERROR(AB8/AA8*100,"N/A") -> N/A | AD8: 3.228576 | AE8: 0.090421 | AF8: =IFERROR(AE8/AD8*100,"N/A") -> 2.8006465 | AG8: =IF(AND(Q8>0, R8=0), IF(IFERROR(ROUND(AC8,8),0)=0, "Group 9: Only Passed | Without variation (no var CV = 0)", "Group 10: Only Passed | With variation (with var CV > 0)"), IF(AND(Q8=0, R8>0), IF(IFERROR(ROUND(AF8,8),0)=0, "Group 11: Only Failed | Without variation (no var CV = 0)", "Group 12: Only Failed | With variation (with var CV > 0)"), IF(AND(Q8>0, R8>0), IF(ROUND(AA8,5)<>ROUND(AD8,5), IF(AND(IFERROR(ROUND(AC8,8),0)=0, IFERROR(ROUND(AF8,8),0)=0), "Group 1: Flaky | Passed (no variation: CV = 0) AND Failed (no variation: CV = 0) | Different Means", IF(AND(IFERROR(ROUND(AC8,8),0)>0, IFERROR(ROUND(AF8,8),0)>0), "Group 2: Flaky | Passed (with variation: CV > 0) AND Failed (with variation: CV > 0) | Different Means", IF(AND(IFERROR(ROUND(AC8,8),0)=0, IFERROR(ROUND(AF8,8),0)>0), "Group 3: Flaky | Passed (no variation: CV = 0) AND Failed (with variation: CV > 0) | Different Means", "Group 4: Flaky | Passed (with variation: CV > 0) AND Failed (no variation: CV = 0) | Different Means"))), IF(AND(IFERROR(ROUND(AC8,8),0)=0, IFERROR(ROUND(AF8,8),0)=0), "Group 5: Flaky | Passed (no var CV = 0) AND Failed (no var CV = 0) | Equal Means", IF(AND(IFERROR(ROUND(AC8,8),0)>0, IFERROR(ROUND(AF8,8),0)>0), "Group 6: Flaky | Passed (with var CV > 0) AND Failed (with var CV > 0) | Equal Means", IF(AND(IFERROR(ROUND(AC8,8),0)=0, IFERROR(ROUND(AF8,8),0)>0), "Group 7: Flaky | Passed (no var CV = 0) AND Failed (with var CV > 0) | Equal Means", "Group 8: Flaky | Passed (with var CV > 0) AND Failed (no var CV = 0) | Equal Means")))), "Invalid"))) -> Group 12: Only Failed | With variation (with var CV > 0) | AH8: 0 | AI8: 100 | AJ8: =IF(AND(AH8>0, AI8>0), "Observed Flaky Test", "Non-observed Flaky Test") -> Non-observed Flaky Test | AK8: 0 | AL8: 0 | AM8: =IFERROR(AL8/AK8*100,"N/A") -> N/A | AN8: 2793162.4 | AO8: 75.425998 | AP8: =IFERROR(AO8/AN8*100,"N/A") -> 0.00270038 | AQ8: =IF(AND(AH8>0, AI8>0), IF(ROUND(N(AK8),5)<>ROUND(N(AN8),5), IF(AND(ROUND(N(AL8),8)=0, ROUND(N(AO8),8)=0), "Group 1: Flaky | Passed (no variation: SD = 0) AND Failed (no variation: SD = 0) | Different Means", IF(AND(ROUND(N(AL8),8)>0, ROUND(N(AO8),8)>0), "Group 2: Flaky | Passed (with variation: SD > 0) AND Failed (with variation: SD > 0) | Different Means", IF(AND(ROUND(N(AL8),8)=0, ROUND(N(AO8),8)>0), "Group 3: Flaky | Passed (no variation: SD = 0) AND Failed (with variation: SD > 0) | Different Means", "Group 4: Flaky | Passed (with variation: SD > 0) AND Failed (no variation: SD = 0) | Different Means"))), IF(AND(ROUND(N(AL8),8)=0, ROUND(N(AO8),8)=0), "Group 5: Flaky | Passed (no var SD = 0) AND Failed (no var SD = 0) | Equal Means", IF(AND(ROUND(N(AL8),8)>0, ROUND(N(AO8),8)>0), "Group 6: Flaky | Passed (with var SD > 0 ) AND Failed (with var SD > 0) | Equal Means", IF(AND(ROUND(N(AL8),8)=0, ROUND(N(AO8),8)>0), "Group 7: Flaky | Passed (no var SD = 0) AND Failed (with var SD > 0) | Equal Means", "Group 8: Flaky | Passed (with var SD > 0 ) AND Failed (no var SD = 0) | Equal Means"))) ), IF(AH8>0, IF(N(AL8)>0, "Group 10: Only Passed | With variation (with var SD > 0)", "Group 9: Only Passed | Without variation (no var SD = 0)"), IF(AI8>0, IF(N(AO8)>0, "Group 12: Only Failed | With variation (with var SD > 0)", "Group 11: Only Failed | Without variation (no var SD = 0)"), "Invalid: No Executions (Y=0, Z=0)" ) ) ) -> Group 12: Only Failed | With variation (with var SD > 0) | AR8: =IF(OR(F8="Observed Flaky Test", I8="Observed Flaky Test", S8="Observed Flaky Test", AJ8="Observed Flaky Test"), "Observed Flaky Test", "Non-observed Flaky Test") -> Non-observed Flaky Test
B9: test_core.py::CliTests::test_cli_create_user_random_password | C9: 749c609f27cec0ad1e51d855b355ed2bb93dd1768b11408bab36cc4ea982e93e | D9: 100 | E9: 0 | F9: =IF(AND(D9>0, E9>0), "Observed Flaky Test", "Non-observed Flaky Test") -> Non-observed Flaky Test | G9: 100 | H9: 0 | I9: =IF(AND(G9>0, H9>0), "Observed Flaky Test", "Non-observed Flaky Test") -> Non-observed Flaky Test | J9: 8.6008 | K9: 0.003919 | L9: =IFERROR(K9/J9*100,"N/A") -> 0.045565529 | M9: 0 | N9: 0 | O9: =IFERROR(N9/M9*100,"N/A") -> N/A | P9: =IF(AND(G9>0, H9=0), IF(ROUND(K9,8)=0, "Group 9: Only Passed | Without variation (SD Passed = 0)", "Group 10: Only Passed | With variation (SD Passed > 0)"), IF(AND(G9=0, H9>0), IF(ROUND(N9,8)=0, "Group 11: Only Failed | Without variation (SD Failed = 0)", "Group 12: Only Failed | With variation (SD Failed > 0)"), IF(AND(G9>0, H9>0), IF(ROUND(J9,5)<>ROUND(M9,5), IF(AND(ROUND(K9,8)=0, ROUND(N9,8)=0), "Group 1: Flaky | Passed (no variation) AND Failed (no variation) | Different Means", IF(AND(ROUND(K9,8)>0, ROUND(N9,8)>0), "Group 2: Flaky | Passed (with variation) AND Failed (with variation) | Different Means", IF(AND(ROUND(K9,8)=0, ROUND(N9,8)>0), "Group 3: Flaky | Passed (no variation) AND Failed (with variation) | Different Means", "Group 4: Flaky | Passed (with variation) AND Failed (no variation) | Different Means"))), IF(AND(ROUND(K9,8)=0, ROUND(N9,8)=0), "Group 5: Flaky | Passed (no variation) AND Failed (no variation) | Equal Means", IF(AND(ROUND(K9,8)>0, ROUND(N9,8)>0), "Group 6: Flaky | Passed (with variation) AND Failed (with variation) | Equal Means", IF(AND(ROUND(K9,8)=0, ROUND(N9,8)>0), "Group 7: Flaky | Passed (no variation) AND Failed (with variation) | Equal Means", "Group 8: Flaky | Passed (with variation) AND Failed (no variation) | Equal Means")))), "Invalid"))) -> Group 10: Only Passed | With variation (SD Passed > 0) | Q9: 100 | R9: 0 | S9: =IF(AND(Q9>0, R9>0), "Observed Flaky Test", "Non-observed Flaky Test") -> Non-observed Flaky Test | T9: 4275150.3 | U9: 117.90716 | V9: =IFERROR(U9/T9*100,"N/A") -> 0.0027579653 | W9: 0 | X9: 0 | Y9: =IFERROR(X9/W9*100,"N/A") -> N/A | Z9: =IF(AND(Q9>0, R9=0), IF(IFERROR(ROUND(V9,8),0)=0, "Group 9: Only Passed | Without variation (no var CV = 0)", "Group 10: Only Passed | With variation (with var CV > 0)"), IF(AND(Q9=0, R9>0), IF(IFERROR(ROUND(Y9,8),0)=0, "Group 11: Only Failed | Without variation (no var CV = 0)", "Group 12: Only Failed | With variation (with var CV > 0)"), IF(AND(Q9>0, R9>0), IF(ROUND(T9,5)<>ROUND(W9,5), IF(AND(IFERROR(ROUND(V9,8),0)=0, IFERROR(ROUND(Y9,8),0)=0), "Group 1: Flaky | Passed (no variation: CV = 0) AND Failed (no variation: CV = 0) | Different Means", IF(AND(IFERROR(ROUND(V9,8),0)>0, IFERROR(ROUND(Y9,8),0)>0), "Group 2: Flaky | Passed (with variation: CV > 0) AND Failed (with variation: CV > 0) | Different Means", IF(AND(IFERROR(ROUND(V9,8),0)=0, IFERROR(ROUND(Y9,8),0)>0), "Group 3: Flaky | Passed (no variation: CV = 0) AND Failed (with variation: CV > 0) | Different Means", "Group 4: Flaky | Passed (with variation: CV > 0) AND Failed (no variation: CV = 0) | Different Means"))), IF(AND(IFERROR(ROUND(V9,8),0)=0, IFERROR(ROUND(Y9,8),0)=0), "Group 5: Flaky | Passed (no var CV = 0) AND Failed (no var CV = 0) | Equal Means", IF(AND(IFERROR(ROUND(V9,8),0)>0, IFERROR(ROUND(Y9,8),0)>0), "Group 6: Flaky | Passed (with var CV > 0) AND Failed (with var CV > 0) | Equal Means", IF(AND(IFERROR(ROUND(V9,8),0)=0, IFERROR(ROUND(Y9,8),0)>0), "Group 7: Flaky | Passed (no var CV = 0) AND Failed (with var CV > 0) | Equal Means", "Group 8: Flaky | Passed (with var CV > 0) AND Failed (no var CV = 0) | Equal Means")))), "Invalid"))) -> Group 10: Only Passed | With variation (with var CV > 0) | AA9: 2.417762 | AB9: 0.11188 | AC9: =IFERROR(AB9/AA9*100,"N/A") -> 4.6274199 | AD9: 0 | AE9: 0 | AF9: =IFERROR(AE9/AD9*100,"N/A") -> N/A | AG9: =IF(AND(Q9>0, R9=0), IF(IFERROR(ROUND(AC9,8),0)=0, "Group 9: Only Passed | Without variation (no var CV = 0)", "Group 10: Only Passed | With variation (with var CV > 0)"), IF(AND(Q9=0, R9>0), IF(IFERROR(ROUND(AF9,8),0)=0, "Group 11: Only Failed | Without variation (no var CV = 0)", "Group 12: Only Failed | With variation (with var CV > 0)"), IF(AND(Q9>0, R9>0), IF(ROUND(AA9,5)<>ROUND(AD9,5), IF(AND(IFERROR(ROUND(AC9,8),0)=0, IFERROR(ROUND(AF9,8),0)=0), "Group 1: Flaky | Passed (no variation: CV = 0) AND Failed (no variation: CV = 0) | Different Means", IF(AND(IFERROR(ROUND(AC9,8),0)>0, IFERROR(ROUND(AF9,8),0)>0), "Group 2: Flaky | Passed (with variation: CV > 0) AND Failed (with variation: CV > 0) | Different Means", IF(AND(IFERROR(ROUND(AC9,8),0)=0, IFERROR(ROUND(AF9,8),0)>0), "Group 3: Flaky | Passed (no variation: CV = 0) AND Failed (with variation: CV > 0) | Different Means", "Group 4: Flaky | Passed (with variation: CV > 0) AND Failed (no variation: CV = 0) | Different Means"))), IF(AND(IFERROR(ROUND(AC9,8),0)=0, IFERROR(ROUND(AF9,8),0)=0), "Group 5: Flaky | Passed (no var CV = 0) AND Failed (no var CV = 0) | Equal Means", IF(AND(IFERROR(ROUND(AC9,8),0)>0, IFERROR(ROUND(AF9,8),0)>0), "Group 6: Flaky | Passed (with var CV > 0) AND Failed (with var CV > 0) | Equal Means", IF(AND(IFERROR(ROUND(AC9,8),0)=0, IFERROR(ROUND(AF9,8),0)>0), "Group 7: Flaky | Passed (no var CV = 0) AND Failed (with var CV > 0) | Equal Means", "Group 8: Flaky | Passed (with var CV > 0) AND Failed (no var CV = 0) | Equal Means")))), "Invalid"))) -> Group 10: Only Passed | With variation (with var CV > 0) | AH9: 100 | AI9: 0 | AJ9: =IF(AND(AH9>0, AI9>0), "Observed Flaky Test", "Non-observed Flaky Test") -> Non-observed Flaky Test | AK9: 2795019 | AL9: 67.887086 | AM9: =IFERROR(AL9/AK9*100,"N/A") -> 0.0024288596 | AN9: 0 | AO9: 0 | AP9: =IFERROR(AO9/AN9*100,"N/A") -> N/A | AQ9: =IF(AND(AH9>0, AI9>0), IF(ROUND(N(AK9),5)<>ROUND(N(AN9),5), IF(AND(ROUND(N(AL9),8)=0, ROUND(N(AO9),8)=0), "Group 1: Flaky | Passed (no variation: SD = 0) AND Failed (no variation: SD = 0) | Different Means", IF(AND(ROUND(N(AL9),8)>0, ROUND(N(AO9),8)>0), "Group 2: Flaky | Passed (with variation: SD > 0) AND Failed (with variation: SD > 0) | Different Means", IF(AND(ROUND(N(AL9),8)=0, ROUND(N(AO9),8)>0), "Group 3: Flaky | Passed (no variation: SD = 0) AND Failed (with variation: SD > 0) | Different Means", "Group 4: Flaky | Passed (with variation: SD > 0) AND Failed (no variation: SD = 0) | Different Means"))), IF(AND(ROUND(N(AL9),8)=0, ROUND(N(AO9),8)=0), "Group 5: Flaky | Passed (no var SD = 0) AND Failed (no var SD = 0) | Equal Means", IF(AND(ROUND(N(AL9),8)>0, ROUND(N(AO9),8)>0), "Group 6: Flaky | Passed (with var SD > 0 ) AND Failed (with var SD > 0) | Equal Means", IF(AND(ROUND(N(AL9),8)=0, ROUND(N(AO9),8)>0), "Group 7: Flaky | Passed (no var SD = 0) AND Failed (with var SD > 0) | Equal Means", "Group 8: Flaky | Passed (with var SD > 0 ) AND Failed (no var SD = 0) | Equal Means"))) ), IF(AH9>0, IF(N(AL9)>0, "Group 10: Only Passed | With variation (with var SD > 0)", "Group 9: Only Passed | Without variation (no var SD = 0)"), IF(AI9>0, IF(N(AO9)>0, "Group 12: Only Failed | With variation (with var SD > 0)", "Group 11: Only Failed | Without variation (no var SD = 0)"), "Invalid: No Executions (Y=0, Z=0)" ) ) ) -> Group 10: Only Passed | With variation (with var SD > 0) | AR9: =IF(OR(F9="Observed Flaky Test", I9="Observed Flaky Test", S9="Observed Flaky Test", AJ9="Observed Flaky Test"), "Observed Flaky Test", "Non-observed Flaky Test") -> Non-observed Flaky Test
B10: test_core.py::CliTests::test_cli_create_user_supplied_password | C10: 107722810b9b7947ac10d83de65d00569336e71a305223bc4df11d8157074d09 | D10: 100 | E10: 0 | F10: =IF(AND(D10>0, E10>0), "Observed Flaky Test", "Non-observed Flaky Test") -> Non-observed Flaky Test | G10: 100 | H10: 0 | I10: =IF(AND(G10>0, H10>0), "Observed Flaky Test", "Non-observed Flaky Test") -> Non-observed Flaky Test | J10: 8.6004 | K10: 0.0028 | L10: =IFERROR(K10/J10*100,"N/A") -> 0.032556625 | M10: 0 | N10: 0 | O10: =IFERROR(N10/M10*100,"N/A") -> N/A | P10: =IF(AND(G10>0, H10=0), IF(ROUND(K10,8)=0, "Group 9: Only Passed | Without variation (SD Passed = 0)", "Group 10: Only Passed | With variation (SD Passed > 0)"), IF(AND(G10=0, H10>0), IF(ROUND(N10,8)=0, "Group 11: Only Failed | Without variation (SD Failed = 0)", "Group 12: Only Failed | With variation (SD Failed > 0)"), IF(AND(G10>0, H10>0), IF(ROUND(J10,5)<>ROUND(M10,5), IF(AND(ROUND(K10,8)=0, ROUND(N10,8)=0), "Group 1: Flaky | Passed (no variation) AND Failed (no variation) | Different Means", IF(AND(ROUND(K10,8)>0, ROUND(N10,8)>0), "Group 2: Flaky | Passed (with variation) AND Failed (with variation) | Different Means", IF(AND(ROUND(K10,8)=0, ROUND(N10,8)>0), "Group 3: Flaky | Passed (no variation) AND Failed (with variation) | Different Means", "Group 4: Flaky | Passed (with variation) AND Failed (no variation) | Different Means"))), IF(AND(ROUND(K10,8)=0, ROUND(N10,8)=0), "Group 5: Flaky | Passed (no variation) AND Failed (no variation) | Equal Means", IF(AND(ROUND(K10,8)>0, ROUND(N10,8)>0), "Group 6: Flaky | Passed (with variation) AND Failed (with variation) | Equal Means", IF(AND(ROUND(K10,8)=0, ROUND(N10,8)>0), "Group 7: Flaky | Passed (no variation) AND Failed (with variation) | Equal Means", "Group 8: Flaky | Passed (with variation) AND Failed (no variation) | Equal Means")))), "Invalid"))) -> Group 10: Only Passed | With variation (SD Passed > 0) | Q10: 100 | R10: 0 | S10: =IF(AND(Q10>0, R10>0), "Observed Flaky Test", "Non-observed Flaky Test") -> Non-observed Flaky Test | T10: 4275014.1 | U10: 185.84437 | V10: =IFERROR(U10/T10*100,"N/A") -> 0.0043472225 | W10: 0 | X10: 0 | Y10: =IFERROR(X10/W10*100,"N/A") -> N/A | Z10: =IF(AND(Q10>0, R10=0), IF(IFERROR(ROUND(V10,8),0)=0, "Group 9: Only Passed | Without variation (no var CV = 0)", "Group 10: Only Passed | With variation (with var CV > 0)"), IF(AND(Q10=0, R10>0), IF(IFERROR(ROUND(Y10,8),0)=0, "Group 11: Only Failed | Without variation (no var CV = 0)", "Group 12: Only Failed | With variation (with var CV > 0)"), IF(AND(Q10>0, R10>0), IF(ROUND(T10,5)<>ROUND(W10,5), IF(AND(IFERROR(ROUND(V10,8),0)=0, IFERROR(ROUND(Y10,8),0)=0), "Group 1: Flaky | Passed (no variation: CV = 0) AND Failed (no variation: CV = 0) | Different Means", IF(AND(IFERROR(ROUND(V10,8),0)>0, IFERROR(ROUND(Y10,8),0)>0), "Group 2: Flaky | Passed (with variation: CV > 0) AND Failed (with variation: CV > 0) | Different Means", IF(AND(IFERROR(ROUND(V10,8),0)=0, IFERROR(ROUND(Y10,8),0)>0), "Group 3: Flaky | Passed (no variation: CV = 0) AND Failed (with variation: CV > 0) | Different Means", "Group 4: Flaky | Passed (with variation: CV > 0) AND Failed (no variation: CV = 0) | Different Means"))), IF(AND(IFERROR(ROUND(V10,8),0)=0, IFERROR(ROUND(Y10,8),0)=0), "Group 5: Flaky | Passed (no var CV = 0) AND Failed (no var CV = 0) | Equal Means", IF(AND(IFERROR(ROUND(V10,8),0)>0, IFERROR(ROUND(Y10,8),0)>0), "Group 6: Flaky | Passed (with var CV > 0) AND Failed (with var CV > 0) | Equal Means", IF(AND(IFERROR(ROUND(V10,8),0)=0, IFERROR(ROUND(Y10,8),0)>0), "Group 7: Flaky | Passed (no var CV = 0) AND Failed (with var CV > 0) | Equal Means", "Group 8: Flaky | Passed (with var CV > 0) AND Failed (no var CV = 0) | Equal Means")))), "Invalid"))) -> Group 10: Only Passed | With variation (with var CV > 0) | AA10: 2.36211 | AB10: 0.095123 | AC10: =IFERROR(AB10/AA10*100,"N/A") -> 4.0270352 | AD10: 0 | AE10: 0 | AF10: =IFERROR(AE10/AD10*100,"N/A") -> N/A | AG10: =IF(AND(Q10>0, R10=0), IF(IFERROR(ROUND(AC10,8),0)=0, "Group 9: Only Passed | Without variation (no var CV = 0)", "Group 10: Only Passed | With variation (with var CV > 0)"), IF(AND(Q10=0, R10>0), IF(IFERROR(ROUND(AF10,8),0)=0, "Group 11: Only Failed | Without variation (no var CV = 0)", "Group 12: Only Failed | With variation (with var CV > 0)"), IF(AND(Q10>0, R10>0), IF(ROUND(AA10,5)<>ROUND(AD10,5), IF(AND(IFERROR(ROUND(AC10,8),0)=0, IFERROR(ROUND(AF10,8),0)=0), "Group 1: Flaky | Passed (no variation: CV = 0) AND Failed (no variation: CV = 0) | Different Means", IF(AND(IFERROR(ROUND(AC10,8),0)>0, IFERROR(ROUND(AF10,8),0)>0), "Group 2: Flaky | Passed (with variation: CV > 0) AND Failed (with variation: CV > 0) | Different Means", IF(AND(IFERROR(ROUND(AC10,8),0)=0, IFERROR(ROUND(AF10,8),0)>0), "Group 3: Flaky | Passed (no variation: CV = 0) AND Failed (with variation: CV > 0) | Different Means", "Group 4: Flaky | Passed (with variation: CV > 0) AND Failed (no variation: CV = 0) | Different Means"))), IF(AND(IFERROR(ROUND(AC10,8),0)=0, IFERROR(ROUND(AF10,8),0)=0), "Group 5: Flaky | Passed (no var CV = 0) AND Failed (no var CV = 0) | Equal Means", IF(AND(IFERROR(ROUND(AC10,8),0)>0, IFERROR(ROUND(AF10,8),0)>0), "Group 6: Flaky | Passed (with var CV > 0) AND Failed (with var CV > 0) | Equal Means", IF(AND(IFERROR(ROUND(AC10,8),0)=0, IFERROR(ROUND(AF10,8),0)>0), "Group 7: Flaky | Passed (no var CV = 0) AND Failed (with var CV > 0) | Equal Means", "Group 8: Flaky | Passed (with var CV > 0) AND Failed (no var CV = 0) | Equal Means")))), "Invalid"))) -> Group 10: Only Passed | With variation (with var CV > 0) | AH10: 100 | AI10: 0 | AJ10: =IF(AND(AH10>0, AI10>0), "Observed Flaky Test", "Non-observed Flaky Test") -> Non-observed Flaky Test | AK10: 2792986.6 | AL10: 78.173767 | AM10: =IFERROR(AL10/AK10*100,"N/A") -> 0.002798931 | AN10: 0 | AO10: 0 | AP10: =IFERROR(AO10/AN10*100,"N/A") -> N/A | AQ10: =IF(AND(AH10>0, AI10>0), IF(ROUND(N(AK10),5)<>ROUND(N(AN10),5), IF(AND(ROUND(N(AL10),8)=0, ROUND(N(AO10),8)=0), "Group 1: Flaky | Passed (no variation: SD = 0) AND Failed (no variation: SD = 0) | Different Means", IF(AND(ROUND(N(AL10),8)>0, ROUND(N(AO10),8)>0), "Group 2: Flaky | Passed (with variation: SD > 0) AND Failed (with variation: SD > 0) | Different Means", IF(AND(ROUND(N(AL10),8)=0, ROUND(N(AO10),8)>0), "Group 3: Flaky | Passed (no variation: SD = 0) AND Failed (with variation: SD > 0) | Different Means", "Group 4: Flaky | Passed (with variation: SD > 0) AND Failed (no variation: SD = 0) | Different Means"))), IF(AND(ROUND(N(AL10),8)=0, ROUND(N(AO10),8)=0), "Group 5: Flaky | Passed (no var SD = 0) AND Failed (no var SD = 0) | Equal Means", IF(AND(ROUND(N(AL10),8)>0, ROUND(N(AO10),8)>0), "Group 6: Flaky | Passed (with var SD > 0 ) AND Failed (with var SD > 0) | Equal Means", IF(AND(ROUND(N(AL10),8)=0, ROUND(N(AO10),8)>0), "Group 7: Flaky | Passed (no var SD = 0) AND Failed (with var SD > 0) | Equal Means", "Group 8: Flaky | Passed (with var SD > 0 ) AND Failed (no var SD = 0) | Equal Means"))) ), IF(AH10>0, IF(N(AL10)>0, "Group 10: Only Passed | With variation (with var SD > 0)", "Group 9: Only Passed | Without variation (no var SD = 0)"), IF(AI10>0, IF(N(AO10)>0, "Group 12: Only Failed | With variation (with var SD > 0)", "Group 11: Only Failed | Without variation (no var SD = 0)"), "Invalid: No Executions (Y=0, Z=0)" ) ) ) -> Group 10: Only Passed | With variation (with var SD > 0) | AR10: =IF(OR(F10="Observed Flaky Test", I10="Observed Flaky Test", S10="Observed Flaky Test", AJ10="Observed Flaky Test"), "Observed Flaky Test", "Non-observed Flaky Test") -> Non-observed Flaky Test
